<?xml version="1.0" encoding="utf-8"?>
<mujoco>
    <include file="../scene/basic_scene.xml"/>
    <include file="kuka_shared_config_v2.xml"></include>
    <worldbody>
        <include file="kuka_xyz_base_v2.xml"></include>

        <body name="door" pos="0.1 0.85 0.1">
                <joint name="doorjoint" pos="-.16 0 0" axis="0 0 1"
                       type="hinge" limited="true" range="-1.5708 0" damping="0.1" armature="0" />
                <geom type="box" pos="0 0 0" size="0.15 0.01 0.1"
                      rgba=".1 .1 .9 1" contype="1" conaffinity="1" material="light_wood"/>
                <!--front, parallel to door-->
                <geom type="box" pos="0.1 -0.15 0.05" size="0.05 0.01 0.02" rgba="0 0 0 1" contype="1" conaffinity="1" name="handle" material="light_wood"/>
                <!--front-->
                <geom type="box" pos="0.14 -0.075 0.05" size="0.01 0.075 0.02" rgba="0 0 0 1" contype="1" conaffinity="1" material="light_wood"/>
        </body>
        <site name="goal" pos="-0.2 0.6 0.15" size="0.02" 
              rgba="0 0.8 0 1"/>
    </worldbody>


    <!-- <actuator>
        <position ctrllimited="true" ctrlrange="-1 1" joint="r_close" kp="400"  user="1"/>
        <position ctrllimited="true" ctrlrange="-1 1" joint="l_close" kp="400"  user="1"/>
    </actuator> -->
    <equality>
        <weld body1="mocap" body2="hand" solref="0.02 1"></weld>
    </equality>

</mujoco>
